[2025-07-18 03:35:54,399][src.utils.utils][INFO] - [rank: 0] Enforcing tags! <cfg.extras.enforce_tags=True>
[2025-07-18 03:35:54,403][src.utils.utils][INFO] - [rank: 0] Printing config tree with Rich! <cfg.extras.print_config=True>
[2025-07-18 03:35:54,446][__main__][INFO] - [rank: 0] Instantiating datamodule <src.data.sevir_datamodule.SEVIRDataModule>
[2025-07-18 03:35:54,447][src.utils.utils][ERROR] - [rank: 0] 
Traceback (most recent call last):
  File "/data0/cjl/.local/lib/python3.8/site-packages/hydra/_internal/utils.py", line 644, in _locate
    obj = getattr(obj, part)
AttributeError: module 'src.data' has no attribute 'sevir_datamodule'

During handling of the above exception, another exception occurred:

Traceback (most recent call last):
  File "/data0/cjl/.local/lib/python3.8/site-packages/hydra/_internal/utils.py", line 650, in _locate
    obj = import_module(mod)
  File "/usr/lib/python3.8/importlib/__init__.py", line 127, in import_module
    return _bootstrap._gcd_import(name[level:], package, level)
  File "<frozen importlib._bootstrap>", line 1014, in _gcd_import
  File "<frozen importlib._bootstrap>", line 991, in _find_and_load
  File "<frozen importlib._bootstrap>", line 973, in _find_and_load_unlocked
ModuleNotFoundError: No module named 'src.data.sevir_datamodule'

The above exception was the direct cause of the following exception:

Traceback (most recent call last):
  File "/data0/cjl/.local/lib/python3.8/site-packages/hydra/_internal/instantiate/_instantiate2.py", line 134, in _resolve_target
    target = _locate(target)
  File "/data0/cjl/.local/lib/python3.8/site-packages/hydra/_internal/utils.py", line 653, in _locate
    raise ImportError(
ImportError: Error loading 'src.data.sevir_datamodule.SEVIRDataModule':
ModuleNotFoundError("No module named 'src.data.sevir_datamodule'")
Are you sure that 'sevir_datamodule' is importable from module 'src.data'?

The above exception was the direct cause of the following exception:

Traceback (most recent call last):
  File "/data0/cjl/code/nowcasting/2025_0712sevir测试/lightning-hydra-template/src/utils/utils.py", line 68, in wrap
    metric_dict, object_dict = task_func(cfg=cfg)
  File "src/train.py", line 58, in train
    datamodule: LightningDataModule = hydra.utils.instantiate(cfg.data)
  File "/data0/cjl/.local/lib/python3.8/site-packages/hydra/_internal/instantiate/_instantiate2.py", line 226, in instantiate
    return instantiate_node(
  File "/data0/cjl/.local/lib/python3.8/site-packages/hydra/_internal/instantiate/_instantiate2.py", line 333, in instantiate_node
    _target_ = _resolve_target(node.get(_Keys.TARGET), full_key)
  File "/data0/cjl/.local/lib/python3.8/site-packages/hydra/_internal/instantiate/_instantiate2.py", line 139, in _resolve_target
    raise InstantiationException(msg) from e
hydra.errors.InstantiationException: Error locating target 'src.data.sevir_datamodule.SEVIRDataModule', set env var HYDRA_FULL_ERROR=1 to see chained exception.
full_key: data
[2025-07-18 03:35:54,448][src.utils.utils][INFO] - [rank: 0] Output dir: /data0/cjl/code/nowcasting/2025_0712sevir测试/lightning-hydra-template/logs/train/runs/2025-07-18_03-35-54
